{
  "name": "building_apartment1_floor2_90",
  "refpalette": "c70cities:building_apartment1_floor2_palette_90",
  "xsize": 16,
  "zsize": 16,
  "slices": [
    [
      "                ",
      " aaaaaaaaa      ",
      " abbbbbbbbdeei  ",
      " abbbbbbbbbbfh  ",
      " abbbbbbbbbb g  ",
      " abbbbbbbbc  d  ",
      " abbbbbbbbbbbba ",
      " abbbbbbbbbbbba ",
      " abbbbbbbbbbbba ",
      " abbbbbbbbbbbba ",
      " abbbbbbbbbbbba ",
      " abbbbbbbbbbbba ",
      " abbbbbbbbbbbba ",
      " abbbbbbbbbbbba ",
      " aaaaaaaaaaaaaa ",
      "                "
    ],
    [
      "                ",
      " luuuuuuuu      ",
      " kowBDqI qdddd  ",
      " kt  CqI M SVd  ",
      " k!   qqJq   X  ",
      " kqqy q  q   X  ",
      " k  y q  qqqqqZ ",
      " ks A q  L RU Z ",
      " kr y A  L    Z ",
      " kqxqqq  K QQ Z ",
      " kp   E       Z ",
      " kow DqFJF    Z ",
      " kow Cqs qO   Z ",
      " kn   qr qNPTWZ ",
      " jmmmmmmmmmmmmY ",
      "                "
    ],
    [
      "                ",
      " q000qqqqq      ",
      " q48# q  qhXdd  ",
      " q    q  )  Sd  ",
      " q    qq&q  [d  ",
      " qqqy q  q   d  ",
      " q37y q  qqqqqq ",
      " q  @ q  ( ++ ^ ",
      " q  y @      \\0 ",
      " qq6qqq  *   }0 ",
      " q2   %      }0 ",
      " q    qF&F   }0 ",
      " q    q  q   {0 ",
      " q159 q  q  -]^ ",
      " q000q$^^$^^^^$ ",
      "                "
    ],
    [
      "                ",
      " q000qq00q      ",
      " q:'. q  qddd\u00a4  ",
      " 0    q  q   \u00a3  ",
      " 0    qqqq  /d  ",
      " qqqy q  q  Vd  ",
      " q` y q  qqqqqq ",
      " 0  y q       ^ ",
      " 0  y q      ?0 ",
      " qqqqqq      >0 ",
      " q    q      >0 ",
      " 0    qFFF   >0 ",
      " 0    q  q   <0 ",
      " q|;, q  q    ^ ",
      " q000q$00$^000$ ",
      "                "
    ],
    [
      "                ",
      " q^^^qq^^q      ",
      " q    q  q\u00a3\u00a3\u00a3d  ",
      " k    q fq   X  ",
      " k    qqqq   X  ",
      " qqqy q  q \u00a5/e  ",
      " q  y q  qqqqqq ",
      " k  y q       ^ ",
      " k  y q       ^ ",
      " qqqqqq       ^ ",
      " q    q       ^ ",
      " k    qFFF    ^ ",
      " k    q  q    ^ ",
      " q    q  q    ^ ",
      " q^^^q$^^$^^^^$ ",
      "                "
    ],
    [
      "                ",
      " qqqqqqqqq      ",
      " qddddqddqdddd  ",
      " qddddqddq   d  ",
      " qddddqqqq   d  ",
      " qddddqddqVc d  ",
      " q\u00a7\u00a7ddqddqqqqqq ",
      " q\u00a7\u00a7ddqdddddddq ",
      " q\u00a7\u00a7ddqdddddddq ",
      " qqqqqqdddddddq ",
      " qddddqdddddddq ",
      " qddddqdddddddq ",
      " qddddq\u00a7\u00a7dddddq ",
      " qddddq\u00a7\u00a7dddddq ",
      " qqqqqqqqqqqqqq ",
      "                "
    ]
  ]
}