{
  "name": "building_bank1_base1",
  "refpalette": "c70cities:building_bank1_base1_palette",
  "xsize": 16,
  "zsize": 16,
  "slices": [
    [
      "vvvvvvvvvvvvvvvv",
      "vaabbaaaabbaaaav",
      "vab!bbbbbbbbbbav",
      "vabbbbbbbbbbbbbv",
      "vabbbbbbbbbbbbbv",
      "vbbbbbbbbbbbbbav",
      "vbbbbbbbbbbbbbav",
      "vabbbbbbbbbbbbav",
      "vabbbbbbbbbbbbav",
      "vabbbbbbbbbbbbbv",
      "vabbbbbbbbbbbbbv",
      "vbbbbbbbbbbbbbav",
      "vbbbbbbbbbbbbbav",
      "vabbbbbbbbb!bbav",
      "vaaaabbaaaabbaav",
      "vvvvvvvvvvvvvvvv"
    ],
    [
      "vvvvvvvvvvvvvvvv",
      "vaabbaaaabbaaaav",
      "va ccd eecc efav",
      "vae  e       cbv",
      "va           cbv",
      "vbc          eav",
      "vbc     e    eav",
      "vag    hih   eav",
      "vad    ihi   eav",
      "vag   ehih   cbv",
      "vae          cbv",
      "vbc          dav",
      "vbcj         gav",
      "va   cceeeecckav",
      "vaaaabbaaaabbaav",
      "vvvvvvvvvvvvvvvv"
    ],
    [
      "vvvvvvvvvvvvvvvv",
      "vaabbaaaabbaaaav",
      "va cc  l cc  mav",
      "va           cbv",
      "va           cbv",
      "vbc           av",
      "vbc          lav",
      "val    nnn   lav",
      "vad    ooo    av",
      "va     ooo   cbv",
      "va           cbv",
      "vbc          dav",
      "vbcj          av",
      "va   cclgl ccgav",
      "vaaaabbaaaabbaav",
      "vvvvvvvvvvvvvvvv"
    ],
    [
      "vvvvvvvvvvvvvvvv",
      "vaabbaaaabbaaaav",
      "va cc    cc   av",
      "va           cbv",
      "va           cbv",
      "vbc           av",
      "vbc           av",
      "va            av",
      "va      o     av",
      "va           cbv",
      "va           cbv",
      "vbc           av",
      "vbcj          av",
      "va   cc    cc av",
      "vaaaabbaaaabbaav",
      "vvvvvvvvvvvvvvvv"
    ],
    [
      "vvvvvvvvvvvvvvvv",
      "vaabbaaaabbaaaav",
      "va cc    cc   av",
      "va           cbv",
      "va           cbv",
      "vbc           av",
      "vbc           av",
      "va            av",
      "va            av",
      "va           cbv",
      "va           cbv",
      "vbc           av",
      "vbcj          av",
      "va   cc    cc av",
      "vaaaabbaaaabbaav",
      "vvvvvvvvvvvvvvvv"
    ],
    [
      "vvvvvvvvvvvvvvvv",
      "vaabbaaaabbaaaav",
      "vamccppppccppqav",
      "vapppppppppppcbv",
      "vapppppppppppcbv",
      "vbcpppppppppppav",
      "vbcpppppppppppav",
      "vappppppppppppav",
      "vappppppppppppav",
      "vapppppppppppcbv",
      "vapppppppppppcbv",
      "vbcpppppppppppav",
      "vbcjppppppppppav",
      "varppccppppccmav",
      "vaaaabbaaaabbaav",
      "vvvvvvvvvvvvvvvv"
    ]
  ]
}