{
  "name": "building_bank1_base1_180",
  "refpalette": "c70cities:building_bank1_base1_palette_180",
  "xsize": 16,
  "zsize": 16,
  "slices": [
    [
      "vvvvvvvvvvvvvvvv",
      "vaabbaaaabbaaaav",
      "vabb!bbbbbbbbbav",
      "vabbbbbbbbbbbbbv",
      "vabbbbbbbbbbbbbv",
      "vbbbbbbbbbbbbbav",
      "vbbbbbbbbbbbbbav",
      "vabbbbbbbbbbbbav",
      "vabbbbbbbbbbbbav",
      "vabbbbbbbbbbbbbv",
      "vabbbbbbbbbbbbbv",
      "vbbbbbbbbbbbbbav",
      "vbbbbbbbbbbbbbav",
      "vabbbbbbbbbb!bav",
      "vaaaabbaaaabbaav",
      "vvvvvvvvvvvvvvvv"
    ],
    [
      "vvvvvvvvvvvvvvvv",
      "vaabbaaaabbaaaav",
      "vakcceeeecc   av",
      "vag         jcbv",
      "vad          cbv",
      "vbc          eav",
      "vbc   hihe   gav",
      "vae   ihi    dav",
      "vae   hih    gav",
      "vae    e     cbv",
      "vae          cbv",
      "vbc           av",
      "vbc       e  eav",
      "vafe ccee dcc av",
      "vaaaabbaaaabbaav",
      "vvvvvvvvvvvvvvvv"
    ],
    [
      "vvvvvvvvvvvvvvvv",
      "vaabbaaaabbaaaav",
      "vagcc lglcc   av",
      "va          jcbv",
      "vad          cbv",
      "vbc           av",
      "vbc   ooo     av",
      "va    ooo    dav",
      "val   nnn    lav",
      "val          cbv",
      "va           cbv",
      "vbc           av",
      "vbc           av",
      "vam  cc l  cc av",
      "vaaaabbaaaabbaav",
      "vvvvvvvvvvvvvvvv"
    ],
    [
      "vvvvvvvvvvvvvvvv",
      "vaabbaaaabbaaaav",
      "va cc    cc   av",
      "va          jcbv",
      "va           cbv",
      "vbc           av",
      "vbc           av",
      "va     o      av",
      "va            av",
      "va           cbv",
      "va           cbv",
      "vbc           av",
      "vbc           av",
      "va   cc    cc av",
      "vaaaabbaaaabbaav",
      "vvvvvvvvvvvvvvvv"
    ],
    [
      "vvvvvvvvvvvvvvvv",
      "vaabbaaaabbaaaav",
      "va cc    cc   av",
      "va          jcbv",
      "va           cbv",
      "vbc           av",
      "vbc           av",
      "va            av",
      "va            av",
      "va           cbv",
      "va           cbv",
      "vbc           av",
      "vbc           av",
      "va   cc    cc av",
      "vaaaabbaaaabbaav",
      "vvvvvvvvvvvvvvvv"
    ],
    [
      "vvvvvvvvvvvvvvvv",
      "vaabbaaaabbaaaav",
      "vamccppppccpprav",
      "vappppppppppjcbv",
      "vapppppppppppcbv",
      "vbcpppppppppppav",
      "vbcpppppppppppav",
      "vappppppppppppav",
      "vappppppppppppav",
      "vapppppppppppcbv",
      "vapppppppppppcbv",
      "vbcpppppppppppav",
      "vbcpppppppppppav",
      "vaqppccppppccmav",
      "vaaaabbaaaabbaav",
      "vvvvvvvvvvvvvvvv"
    ]
  ]
}