{
  "name": "building_apartment1_floor1_270",
  "refpalette": "c70cities:building_apartment1_floor1_palette_270",
  "xsize": 16,
  "zsize": 16,
  "slices": [
    [
      "                ",
      " aaaaaaaaaaaaaa ",
      " abbbbbbbbbbbba ",
      " abbbbbbbbbbbba ",
      " abbbbbbbbbbbba ",
      " abbbbbbbbbbbba ",
      " abbbbbbbbbbbba ",
      " abbbbbbbbbbbba ",
      " abbbbbbbbbbbba ",
      " abbbbbbbbbbbba ",
      "  d  cbbbbbbbba ",
      "  g bbbbbbbbbba ",
      "  hfbbbbbbbbbba ",
      "  ieedbbbbbbbba ",
      "      aaaaaaaaa ",
      "                "
    ],
    [
      "                ",
      " Xmmmmmmmmmmmmj ",
      " YVSOMp qp    k ",
      " Y   Np rpB unk ",
      " Y    EIEpC unk ",
      " Y       D   ok ",
      " Y PP J  pppwpk ",
      " Y    K  y x qk ",
      " Y!TQ K  p y rk ",
      " Yppppp  p x  k ",
      "  W   p  p xppk ",
      "  W   pIpp  unk ",
      "  dUR L FpB   k ",
      "  ddddp FpCA sk ",
      "      ttttttttl ",
      "                "
    ],
    [
      "                ",
      " #%%%%#%%#pZZZp ",
      " %-)  p  p 740p ",
      " Z[  *p  p    p ",
      " Z]   E^Ep    p ",
      " Z]      $   1p ",
      " Z]      ppp5pp ",
      " Z{      8 x  p ",
      " % ((    p 8  p ",
      " pppppp  p x 2p ",
      "  d   p  p xppp ",
      "  d+  p^pp  unp ",
      "  dR  &  p    p ",
      "  ddWhp  p@963p ",
      "      pppppZZZp ",
      "                "
    ],
    [
      "                ",
      " #ZZZ%#ZZ#pZZZp ",
      " %    p  p ;`}p ",
      " Z.   p  p    Z ",
      " Z/   EEEp    Z ",
      " Z/      p    p ",
      " Z/      pppppp ",
      " Z<      p x  Z ",
      " %       p x  Z ",
      " pppppp  p x \\p ",
      "  dU  p  p xppp ",
      "  d,  pppp    Z ",
      "  >   p  p    Z ",
      "  ?dddp  p ':|p ",
      "      pZZppZZZp ",
      "                "
    ],
    [
      "                ",
      " #%%%%#%%#p%%%p ",
      " %    p  p    p ",
      " %    p  p    k ",
      " %    EEEp    k ",
      " %       p    p ",
      " %       pppppp ",
      " %       p x  k ",
      " %       p x  k ",
      " pppppp  p x  p ",
      "  e,\u00a3 p  p xppp ",
      "  W   pppp    k ",
      "  W   pf p    k ",
      "  d>>>p  p    p ",
      "      p%%pp%%%p ",
      "                "
    ],
    [
      "                ",
      " pppppppppppppp ",
      " pddddd\u00a4\u00a4pddddp ",
      " pddddd\u00a4\u00a4pddddp ",
      " pdddddddpddddp ",
      " pdddddddpddddp ",
      " pdddddddpppppp ",
      " pdddddddpdd\u00a4\u00a4p ",
      " pdddddddpdd\u00a4\u00a4p ",
      " ppppppddpdd\u00a4\u00a4p ",
      "  d cUpddpddddp ",
      "  d   ppppddddp ",
      "  d   pddpddddp ",
      "  ddddpddpddddp ",
      "      ppppppppp ",
      "                "
    ]
  ]
}