{
  "name": "building_bank1_base1_270",
  "refpalette": "c70cities:building_bank1_base1_palette_270",
  "xsize": 16,
  "zsize": 16,
  "slices": [
    [
      "vvvvvvvvvvvvvvvv",
      "vaabbaaaabbaaaav",
      "vabbbbbbbbbbbbav",
      "vabbbbbbbbbbb!bv",
      "vabbbbbbbbbbbbbv",
      "vbbbbbbbbbbbbbav",
      "vbbbbbbbbbbbbbav",
      "vabbbbbbbbbbbbav",
      "vabbbbbbbbbbbbav",
      "vabbbbbbbbbbbbbv",
      "vabbbbbbbbbbbbbv",
      "vb!bbbbbbbbbbbav",
      "vbbbbbbbbbbbbbav",
      "vabbbbbbbbbbbbav",
      "vaaaabbaaaabbaav",
      "vvvvvvvvvvvvvvvv"
    ],
    [
      "vvvvvvvvvvvvvvvv",
      "vaabbaaaabbaaaav",
      "va ccegdgcc e av",
      "va j         cbv",
      "va           cbv",
      "vbc         edav",
      "vbc   e       av",
      "vae   hih    eav",
      "vae   ihie   eav",
      "vae   hih    cbv",
      "vae          cbv",
      "vbc           av",
      "vbc          eav",
      "vakgdcceeeeccfav",
      "vaaaabbaaaabbaav",
      "vvvvvvvvvvvvvvvv"
    ],
    [
      "vvvvvvvvvvvvvvvv",
      "vaabbaaaabbaaaav",
      "va cc  dlcc   av",
      "va j         cbv",
      "va           cbv",
      "vbc           av",
      "vbc           av",
      "val   oon    lav",
      "vag   oon     av",
      "val   oon    cbv",
      "va           cbv",
      "vbc           av",
      "vbc           av",
      "vag dcc ll ccmav",
      "vaaaabbaaaabbaav",
      "vvvvvvvvvvvvvvvv"
    ],
    [
      "vvvvvvvvvvvvvvvv",
      "vaabbaaaabbaaaav",
      "va cc    cc   av",
      "va j         cbv",
      "va           cbv",
      "vbc           av",
      "vbc           av",
      "va            av",
      "va     o      av",
      "va           cbv",
      "va           cbv",
      "vbc           av",
      "vbc           av",
      "va   cc    cc av",
      "vaaaabbaaaabbaav",
      "vvvvvvvvvvvvvvvv"
    ],
    [
      "vvvvvvvvvvvvvvvv",
      "vaabbaaaabbaaaav",
      "va cc    cc   av",
      "va j         cbv",
      "va           cbv",
      "vbc           av",
      "vbc           av",
      "va            av",
      "va            av",
      "va           cbv",
      "va           cbv",
      "vbc           av",
      "vbc           av",
      "va   cc    cc av",
      "vaaaabbaaaabbaav",
      "vvvvvvvvvvvvvvvv"
    ],
    [
      "vvvvvvvvvvvvvvvv",
      "vaabbaaaabbaaaav",
      "varccppppccppmav",
      "vapjpppppppppcbv",
      "vapppppppppppcbv",
      "vbcpppppppppppav",
      "vbcpppppppppppav",
      "vappppppppppppav",
      "vappppppppppppav",
      "vapppppppppppcbv",
      "vapppppppppppcbv",
      "vbcpppppppppppav",
      "vbcpppppppppppav",
      "vamppccppppccqav",
      "vaaaabbaaaabbaav",
      "vvvvvvvvvvvvvvvv"
    ]
  ]
}