{
  "name": "building_apartment1_floor2",
  "refpalette": "c70cities:building_apartment1_floor2_palette",
  "xsize": 16,
  "zsize": 16,
  "slices": [
    [
      "                ",
      " aaaaaaaaaaaaaa ",
      " abbbbbbbbbbbba ",
      " abbbbbbbbbbbba ",
      " abbbbbbbbbbbba ",
      " abbbbbbbbbbbba ",
      " abbbbbbbbbbbba ",
      " abbbbbbbbbbbba ",
      " abbbbbbbbbbbba ",
      " abbbbbbbbbbbba ",
      " abbbbbbbbcbbd  ",
      " abbbbbbbb bbe  ",
      " abbbbbbbb  fe  ",
      " abbbbbbbbdghi  ",
      " aaaaaaaaa      ",
      "                "
    ],
    [
      "                ",
      " jkkkkkkkkkkkkl ",
      " mnoopqrs q!tou ",
      " m ww x   q  wu ",
      " m    qyAyy  Bu ",
      " m CD q     CDu ",
      " mqqqEqAqqqqqqu ",
      " mrsF      qIIu ",
      " m  J      J  u ",
      " mqqF KLLqqqMqu ",
      " mNO     q   d  ",
      " mP   Q Rq  Sd  ",
      " mT   Q Uq  Vd  ",
      " mW      qXXdd  ",
      " YZZZZZZZZ      ",
      "                "
    ],
    [
      "                ",
      " qqqqqqqqqqqqqq ",
      " 01  2q  3q  40 ",
      " 05   6  7q  80 ",
      " 09   qy@yy  #0 ",
      " q    q       q ",
      " $qqq%q@qqqqqqq ",
      " ^  F      q  q ",
      " ^  &      &  q ",
      " $qqF * (qqq)qq ",
      " ^       q   h  ",
      " ^      +q   X  ",
      " ^-     +q [Sd  ",
      " ^]{}}}\\ qdddd  ",
      " $^00000^q      ",
      "                "
    ],
    [
      "                ",
      " qq00qq00qq00qq ",
      " 0|   q  `q  :0 ",
      " 0;   q   q  '0 ",
      " 0,   qyyyy  .0 ",
      " q    q       q ",
      " $qqqqqqqqqqqqq ",
      " 0  F      q  0 ",
      " 0  F      q  0 ",
      " $qqF    qqqqqq ",
      " ^       q   d  ",
      " 0       q   d  ",
      " 0       qV/ d  ",
      " 0 <>>>? qdd\u00a3\u00a4  ",
      " $^00000^q      ",
      "                "
    ],
    [
      "                ",
      " qqkkqqkkqqkkqq ",
      " ^    q   q   ^ ",
      " ^    q   q   ^ ",
      " ^    qyyyy   ^ ",
      " q    q       q ",
      " $qqqqqqqqqqqqq ",
      " ^  F      q  ^ ",
      " ^  F      qf ^ ",
      " $qqF    qqqqqq ",
      " ^       q   \u00a3  ",
      " ^       q\u00a5  \u00a3  ",
      " ^       q/  \u00a3  ",
      " ^       qeXXd  ",
      " $^^^^^^^q      ",
      "                "
    ],
    [
      "                ",
      " qqqqqqqqqqqqqq ",
      " qddddq\u00a7\u00a7\u00a7ddddq ",
      " qddddq\u00a7\u00a7\u00a7ddddq ",
      " qddddqdddddddq ",
      " qddddqdddddddq ",
      " qqqqqqqqqqqqqq ",
      " q\u00a7\u00a7dddddddqddq ",
      " q\u00a7\u00a7dddddddqddq ",
      " qdddddddqqqqqq ",
      " qdddddddqV  d  ",
      " qdddddddqc  d  ",
      " qdddddddq   d  ",
      " qdddddddqdddd  ",
      " qqqqqqqqq      ",
      "                "
    ]
  ]
}