{
  "name": "building_bunker1_base1_90",
  "refpalette": "c70cities:building_bunker1_base1_palette_90",
  "xsize": 16,
  "zsize": 16,
  "slices": [
    [
      "vvvvvvvvvvvvvvvv",
      "v==============v",
      "v=aaaa=========v",
      "v=aaaa=========v",
      "v=aaaa=========v",
      "v=aaaa=========v",
      "v=aaaa====aaaaav",
      "v=aaaa====aaaaav",
      "v==========a=a=v",
      "v=========aa=aav",
      "v=========aa=aav",
      "v=========aa=aav",
      "v==============v",
      "v==============v",
      "v==============v",
      "vvvvvvvvvvvvvvvv"
    ],
    [
      "vvvvvvvvvvvvvvvv",
      "vbbbbbbbbbbbbbbv",
      "vbiknquyDIMIbSXv",
      "vbh  r y   Qb Wv",
      "vbg  q     Pb Vv",
      "vbe     CbbbbRbv",
      "vbf      F    Uv",
      "vbe  pt nbn   Uv",
      "vbbbmbbxbEbObObv",
      "vbd  b   bL b Tv",
      "vbd  bs  bK b Kv",
      "vbd  bswobJNbNJv",
      "vbb  bbbbbbbbbbv",
      "vbc     Bbzzzzzv",
      "vbcjlo sAbzzzzzv",
      "vvvvvvvvvvvvvvvv"
    ],
    [
      "vvvvvvvvvvvvvvvv",
      "vZ44EEEEEEEEE]]v",
      "vY  69   ^ )E `v",
      "vY   8     (E[|v",
      "vY         *E[\\v",
      "vE3      EEEE-Ev",
      "vE2      %     v",
      "vEL  7  6E6   Tv",
      "vEEE5EE#EEE&E&Ev",
      "vE   E   EL E Tv",
      "vE   E   E1 E }v",
      "vE   Esw E02E+{v",
      "vEE  EEEEEEEEEEv",
      "vE1     $Ezzzzzv",
      "vE0 o  @AEzzzzzv",
      "vvvvvvvvvvvvvvvv"
    ],
    [
      "vvvvvvvvvvvvvvvv",
      "vEEEEEEEEEEEEEEv",
      "vE' 6    ,,?E \u00c0v",
      "vE'        >E\u00a4\u00a7v",
      "vE'        <E\u00a3 v",
      "vE'      EEEEEEv",
      "vE'      E    \u00a5v",
      "vE'     6E6   \u00a5v",
      "vEEEEEE]EEEEEEEv",
      "vE;  E   E /E/ v",
      "vE;  E   E. E  v",
      "vE;  E w Ef E fv",
      "vEE  EEEEEEEEEEv",
      "vE:     !Ezzzzzv",
      "vE      AEzzzzzv",
      "vvvvvvvvvvvvvvvv"
    ],
    [
      "vvvvvvvvvvvvvvvv",
      "vEEEEEEEEEEEEEEv",
      "vE\u00c3\u00c1\u00c1\u00c1\u00c1\u00c1\u00c1EEEE\u00c3\u00c3v",
      "vE\u00c3\u00c1\u00c1\u00c1\u00c1\u00c1\u00c1\u00c3\u00c3\u00c3E\u00c1\u00c1v",
      "vE\u00c3\u00c1\u00c1\u00c1\u00c1\u00c1\u00c1EEEE\u00c1\u00c1v",
      "vE\u00c3\u00c1\u00c1\u00c1\u00c1\u00c1\u00c1EEEEEEv",
      "vE\u00c3\u00c1\u00c1\u00c1\u00c1\u00c1\u00c1E\u00c1\u00c1\u00c1\u00c1\u00c3v",
      "vE\u00c3\u00c1\u00c1\u00c1\u00c1\u00c1\u00c1E\u00c1\u00c1\u00c1\u00c1\u00c3v",
      "vEEEEEEEEEEEEEEv",
      "vE\u00c2\u00c1\u00c1EEEEE\u00c1\u00c1E\u00c1\u00c1v",
      "vE\u00c2\u00c1\u00c1EEEEE\u00c1\u00c1E\u00c1\u00c1v",
      "vE\u00c2\u00c1\u00c1EEwEE\u00c3\u00c4E\u00c4\u00c3v",
      "vEE\u00c4\u00c3EEEEEEEEEEv",
      "vE\u00c1\u00c1\u00c1\u00c3\u00c1\u00c1\u00c1Ezzzzzv",
      "vE\u00c1\u00c1\u00c1\u00c3\u00c1\u00c1AEzzzzzv",
      "vvvvvvvvvvvvvvvv"
    ],
    [
      "vvvvvvvvvvvvvvvv",
      "vzzzzzzzzzzzzzzv",
      "vzzzzzzzzzzzzzzv",
      "vzzzzzzzzzzzzzzv",
      "vzzzzzzzzzzzzzzv",
      "vzzzzzzzzzzzzzzv",
      "vzzzzzzzzzzzzzzv",
      "vzzzzzzzzzzzzzzv",
      "vzzzzzzzzzzzzzzv",
      "vzzzzzzzzzzzzzzv",
      "vzzzzzzEzzzzzzzv",
      "vzzzzzEwEzzzzzzv",
      "vzzzzzzEzzzzzzzv",
      "vzzzzzzzzzzzzzzv",
      "vzzzzzzzzzzzzzzv",
      "vvvvvvvvvvvvvvvv"
    ]
  ]
}