{
  "name": "building_apartment1_floor2_180",
  "refpalette": "c70cities:building_apartment1_floor2_palette_180",
  "xsize": 16,
  "zsize": 16,
  "slices": [
    [
      "                ",
      "      aaaaaaaaa ",
      "  ihgdbbbbbbbba ",
      "  ef  bbbbbbbba ",
      "  ebb bbbbbbbba ",
      "  dbbcbbbbbbbba ",
      " abbbbbbbbbbbba ",
      " abbbbbbbbbbbba ",
      " abbbbbbbbbbbba ",
      " abbbbbbbbbbbba ",
      " abbbbbbbbbbbba ",
      " abbbbbbbbbbbba ",
      " abbbbbbbbbbbba ",
      " abbbbbbbbbbbba ",
      " aaaaaaaaaaaaaa ",
      "                "
    ],
    [
      "                ",
      "      ZZZZZZZZY ",
      "  ddXXq      Wm ",
      "  dV  qU Q   Tm ",
      "  dS  qR Q   Pm ",
      "  d   q     ONm ",
      " uqMqqqLLK Fqqm ",
      " u  J      J  m ",
      " uIIq      Fsrm ",
      " uqqqqqqAqEqqqm ",
      " uDC     q DC m ",
      " uB  yyAyq    m ",
      " uw  q   x ww m ",
      " uot!q srqpoonm ",
      " lkkkkkkkkkkkkj ",
      "                "
    ],
    [
      "                ",
      "      q^00000^$ ",
      "  ddddq \\}}}{]^ ",
      "  dS[ q+     -^ ",
      "  X   q+      ^ ",
      "  h   q       ^ ",
      " qq)qqq( * Fqq$ ",
      " q  &      &  ^ ",
      " q  q      F  ^ ",
      " qqqqqqq@q%qqq$ ",
      " q       q    q ",
      " 0#  yy@yq   90 ",
      " 08  q7  6   50 ",
      " 04  q3  q2  10 ",
      " qqqqqqqqqqqqqq ",
      "                "
    ],
    [
      "                ",
      "      q^00000^$ ",
      "  \u00a4\u00a3ddq ?>>>< 0 ",
      "  d /Vq       0 ",
      "  d   q       0 ",
      "  d   q       ^ ",
      " qqqqqq    Fqq$ ",
      " 0  q      F  0 ",
      " 0  q      F  0 ",
      " qqqqqqqqqqqqq$ ",
      " q       q    q ",
      " 0.  yyyyq   ,0 ",
      " 0'  q   q   ;0 ",
      " 0:  q`  q   |0 ",
      " qq00qq00qq00qq ",
      "                "
    ],
    [
      "                ",
      "      q^^^^^^^$ ",
      "  dXXeq       ^ ",
      "  \u00a3  /q       ^ ",
      "  \u00a3  \u00a5q       ^ ",
      "  \u00a3   q       ^ ",
      " qqqqqq    Fqq$ ",
      " ^ fq      F  ^ ",
      " ^  q      F  ^ ",
      " qqqqqqqqqqqqq$ ",
      " q       q    q ",
      " ^   yyyyq    ^ ",
      " ^   q   q    ^ ",
      " ^   q   q    ^ ",
      " qqkkqqkkqqkkqq ",
      "                "
    ],
    [
      "                ",
      "      qqqqqqqqq ",
      "  ddddqdddddddq ",
      "  d   qdddddddq ",
      "  d  cqdddddddq ",
      "  d  Vqdddddddq ",
      " qqqqqqdddddddq ",
      " qddqddddddd\u00a7\u00a7q ",
      " qddqddddddd\u00a7\u00a7q ",
      " qqqqqqqqqqqqqq ",
      " qdddddddqddddq ",
      " qdddddddqddddq ",
      " qdddd\u00a7\u00a7\u00a7qddddq ",
      " qdddd\u00a7\u00a7\u00a7qddddq ",
      " qqqqqqqqqqqqqq ",
      "                "
    ]
  ]
}