{
  "name": "building_apartment1_floor2_270",
  "refpalette": "c70cities:building_apartment1_floor2_palette_270",
  "xsize": 16,
  "zsize": 16,
  "slices": [
    [
      "                ",
      " aaaaaaaaaaaaaa ",
      " abbbbbbbbbbbba ",
      " abbbbbbbbbbbba ",
      " abbbbbbbbbbbba ",
      " abbbbbbbbbbbba ",
      " abbbbbbbbbbbba ",
      " abbbbbbbbbbbba ",
      " abbbbbbbbbbbba ",
      " abbbbbbbbbbbba ",
      "  d  cbbbbbbbba ",
      "  g bbbbbbbbbba ",
      "  hfbbbbbbbbbba ",
      "  ieedbbbbbbbba ",
      "      aaaaaaaaa ",
      "                "
    ],
    [
      "                ",
      " Ymmmmmmmmmmmmj ",
      " ZWTPNq rq   nk ",
      " Z   Oq sqC wok ",
      " Z    FJFqD wok ",
      " Z       E   pk ",
      " Z QQ K  qqqxqk ",
      " Z    L  A y rk ",
      " Z UR L  q A sk ",
      " Zqqqqq  q y  k ",
      "  X   q  q yqqk ",
      "  X   qJqq   !k ",
      "  dVS M IqC  tk ",
      "  ddddq IqDBwok ",
      "      uuuuuuuul ",
      "                "
    ],
    [
      "                ",
      " $^^^^$^^$q000q ",
      " ^]-  q  q 951q ",
      " 0{   q  q    q ",
      " 0}   F&Fq    q ",
      " 0}      %   2q ",
      " 0}   *  qqq6qq ",
      " 0\\      @ y  q ",
      " ^ ++ (  q @  q ",
      " qqqqqq  q y73q ",
      "  d   q  q yqqq ",
      "  d[  q&qq    q ",
      "  dS  )  q    q ",
      "  ddXhq  q #84q ",
      "      qqqqq000q ",
      "                "
    ],
    [
      "                ",
      " $000^$00$q000q ",
      " ^    q  q ,;|q ",
      " 0<   q  q    0 ",
      " 0>   FFFq    0 ",
      " 0>      q    q ",
      " 0>      qqqqqq ",
      " 0?      q y  0 ",
      " ^       q y  0 ",
      " qqqqqq  q y `q ",
      "  dV  q  q yqqq ",
      "  d/  qqqq    0 ",
      "  \u00a3   q  q    0 ",
      "  \u00a4dddq  q .':q ",
      "      q00qq000q ",
      "                "
    ],
    [
      "                ",
      " $^^^^$^^$q^^^q ",
      " ^    q  q    q ",
      " ^    q  q    k ",
      " ^    FFFq    k ",
      " ^       q    q ",
      " ^       qqqqqq ",
      " ^       q y  k ",
      " ^       q y  k ",
      " qqqqqq  q y  q ",
      "  e/\u00a5 q  q yqqq ",
      "  X   qqqq    k ",
      "  X   qf q    k ",
      "  d\u00a3\u00a3\u00a3q  q    q ",
      "      q^^qq^^^q ",
      "                "
    ],
    [
      "                ",
      " qqqqqqqqqqqqqq ",
      " qddddd\u00a7\u00a7qddddq ",
      " qddddd\u00a7\u00a7qddddq ",
      " qdddddddqddddq ",
      " qdddddddqddddq ",
      " qdddddddqqqqqq ",
      " qdddddddqdd\u00a7\u00a7q ",
      " qdddddddqdd\u00a7\u00a7q ",
      " qqqqqqddqdd\u00a7\u00a7q ",
      "  d cVqddqddddq ",
      "  d   qqqqddddq ",
      "  d   qddqddddq ",
      "  ddddqddqddddq ",
      "      qqqqqqqqq ",
      "                "
    ]
  ]
}