{
  "name": "building_apartment1_floor1_90",
  "refpalette": "c70cities:building_apartment1_floor1_palette_90",
  "xsize": 16,
  "zsize": 16,
  "slices": [
    [
      "                ",
      " aaaaaaaaa      ",
      " abbbbbbbbdeei  ",
      " abbbbbbbbbbfh  ",
      " abbbbbbbbbb g  ",
      " abbbbbbbbc  d  ",
      " abbbbbbbbbbbba ",
      " abbbbbbbbbbbba ",
      " abbbbbbbbbbbba ",
      " abbbbbbbbbbbba ",
      " abbbbbbbbbbbba ",
      " abbbbbbbbbbbba ",
      " abbbbbbbbbbbba ",
      " abbbbbbbbbbbba ",
      " aaaaaaaaaaaaaa ",
      "                "
    ],
    [
      "                ",
      " ltttttttt      ",
      " ks ACpF pdddd  ",
      " k   BpF L RUd  ",
      " knu  ppIp   W  ",
      " kppx p  p   W  ",
      " k  x p  pppppY ",
      " kr y p  K QT!Y ",
      " kq x y  K    Y ",
      " kpwppp  J PP Y ",
      " ko   D       Y ",
      " knu CpEIE    Y ",
      " knu Bpr pN   Y ",
      " k    pq pMOSVY ",
      " jmmmmmmmmmmmmX ",
      "                "
    ],
    [
      "                ",
      " pZZZppppp      ",
      " p369@p  phWdd  ",
      " p    p  &  Rd  ",
      " pnu  pp^p  +d  ",
      " pppx p  p   d  ",
      " p2 x p  pppppp ",
      " p  8 p    (( % ",
      " p  x 8      {Z ",
      " pp5ppp      ]Z ",
      " p1   $      ]Z ",
      " p    pE^E   ]Z ",
      " p    p  p*  [Z ",
      " p047 p  p  )-% ",
      " pZZZp#%%#%%%%# ",
      "                "
    ],
    [
      "                ",
      " pZZZppZZp      ",
      " p|:' p  pddd?  ",
      " Z    p  p   >  ",
      " Z    pppp  ,d  ",
      " pppx p  p  Ud  ",
      " p\\ x p  pppppp ",
      " Z  x p       % ",
      " Z  x p      <Z ",
      " pppppp      /Z ",
      " p    p      /Z ",
      " Z    pEEE   /Z ",
      " Z    p  p   .Z ",
      " p}`; p  p    % ",
      " pZZZp#ZZ#%ZZZ# ",
      "                "
    ],
    [
      "                ",
      " p%%%pp%%p      ",
      " p    p  p>>>d  ",
      " k    p fp   W  ",
      " k    pppp   W  ",
      " pppx p  p \u00a3,e  ",
      " p  x p  pppppp ",
      " k  x p       % ",
      " k  x p       % ",
      " pppppp       % ",
      " p    p       % ",
      " k    pEEE    % ",
      " k    p  p    % ",
      " p    p  p    % ",
      " p%%%p#%%#%%%%# ",
      "                "
    ],
    [
      "                ",
      " ppppppppp      ",
      " pddddpddpdddd  ",
      " pddddpddp   d  ",
      " pddddpppp   d  ",
      " pddddpddpUc d  ",
      " p\u00a4\u00a4ddpddpppppp ",
      " p\u00a4\u00a4ddpdddddddp ",
      " p\u00a4\u00a4ddpdddddddp ",
      " ppppppdddddddp ",
      " pddddpdddddddp ",
      " pddddpdddddddp ",
      " pddddp\u00a4\u00a4dddddp ",
      " pddddp\u00a4\u00a4dddddp ",
      " pppppppppppppp ",
      "                "
    ]
  ]
}