{
  "name": "building_apartment1_floor1_180",
  "refpalette": "c70cities:building_apartment1_floor1_palette_180",
  "xsize": 16,
  "zsize": 16,
  "slices": [
    [
      "                ",
      "      aaaaaaaaa ",
      "  ihgdbbbbbbbba ",
      "  ef  bbbbbbbba ",
      "  ebb bbbbbbbba ",
      "  dbbcbbbbbbbba ",
      " abbbbbbbbbbbba ",
      " abbbbbbbbbbbba ",
      " abbbbbbbbbbbba ",
      " abbbbbbbbbbbba ",
      " abbbbbbbbbbbba ",
      " abbbbbbbbbbbba ",
      " abbbbbbbbbbbba ",
      " abbbbbbbbbbbba ",
      " aaaaaaaaaaaaaa ",
      "                "
    ],
    [
      "                ",
      "      YYYYYYYYX ",
      "  ddWWp!     Vm ",
      "  dU  pT P   Sm ",
      "  dR  pQ P   Om ",
      "  d   p     NMm ",
      " tpLpppKKJ Eppm ",
      " t  I      I  m ",
      " tFFp      Erqm ",
      " tppppppypDpppm ",
      " tCB     p CB m ",
      " tA  xxyxp    m ",
      " t  up   w uu m ",
      " ts np rqponn m ",
      " lkkkkkkkkkkkkj ",
      "                "
    ],
    [
      "                ",
      "      p%ZZZZZ%# ",
      "  ddddp {]]][-% ",
      "  dR+ p(     )% ",
      "  W   p(      % ",
      "  h   p     * % ",
      " pp&ppp    Epp# ",
      " p  ^      ^  % ",
      " p  p      E  % ",
      " ppppppp8p$ppp# ",
      " p@      p    p ",
      " Z9  xx8xp   7Z ",
      " Z6 up   5   4Z ",
      " Z3 np2  p1  0Z ",
      " pppppppppppppp ",
      "                "
    ],
    [
      "                ",
      "      p%ZZZZZ%# ",
      "  ?>ddp <///. Z ",
      "  d ,Up       Z ",
      "  d   p       Z ",
      "  d   p       % ",
      " pppppp    Epp# ",
      " Z  p      E  Z ",
      " Z  p      E  Z ",
      " ppppppppppppp# ",
      " p       p    p ",
      " Z'  xxxxp   ;Z ",
      " Z:  p   p   `Z ",
      " Z|  p\\  p   }Z ",
      " ppZZppZZppZZpp ",
      "                "
    ],
    [
      "                ",
      "      p%%%%%%%# ",
      "  dWWep       % ",
      "  >  ,p       % ",
      "  >  \u00a3p       % ",
      "  >   p       % ",
      " pppppp    Epp# ",
      " % fp      E  % ",
      " %  p      E  % ",
      " ppppppppppppp# ",
      " p       p    p ",
      " %   xxxxp    % ",
      " %   p   p    % ",
      " %   p   p    % ",
      " ppkkppkkppkkpp ",
      "                "
    ],
    [
      "                ",
      "      ppppppppp ",
      "  ddddpdddddddp ",
      "  d   pdddddddp ",
      "  d  cpdddddddp ",
      "  d  Updddddddp ",
      " ppppppdddddddp ",
      " pddpddddddd\u00a4\u00a4p ",
      " pddpddddddd\u00a4\u00a4p ",
      " pppppppppppppp ",
      " pdddddddpddddp ",
      " pdddddddpddddp ",
      " pdddd\u00a4\u00a4\u00a4pddddp ",
      " pdddd\u00a4\u00a4\u00a4pddddp ",
      " pppppppppppppp ",
      "                "
    ]
  ]
}