{
  "name": "building_apartment1_floor1",
  "refpalette": "c70cities:building_apartment1_floor1_palette",
  "xsize": 16,
  "zsize": 16,
  "slices": [
    [
      "                ",
      " aaaaaaaaaaaaaa ",
      " abbbbbbbbbbbba ",
      " abbbbbbbbbbbba ",
      " abbbbbbbbbbbba ",
      " abbbbbbbbbbbba ",
      " abbbbbbbbbbbba ",
      " abbbbbbbbbbbba ",
      " abbbbbbbbbbbba ",
      " abbbbbbbbbbbba ",
      " abbbbbbbbcbbd  ",
      " abbbbbbbb bbe  ",
      " abbbbbbbb  fe  ",
      " abbbbbbbbdghi  ",
      " aaaaaaaaa      ",
      "                "
    ],
    [
      "                ",
      " jkkkkkkkkkkkkl ",
      " m nnopqr pn st ",
      " m uu w   pu  t ",
      " m    pxyxx  At ",
      " m BC p     BCt ",
      " mpppDpyppppppt ",
      " mqrE      pFFt ",
      " m  I      I  t ",
      " mppE JKKpppLpt ",
      " mMN     p   d  ",
      " mO   P Qp  Rd  ",
      " mS   P Tp  Ud  ",
      " mV     !pWWdd  ",
      " XYYYYYYYY      ",
      "                "
    ],
    [
      "                ",
      " pppppppppppppp ",
      " Z0  1p  2pn 3Z ",
      " Z4   5   pu 6Z ",
      " Z7   px8xx  9Z ",
      " p    p      @p ",
      " #ppp$p8ppppppp ",
      " %  E      p  p ",
      " %  ^      ^  p ",
      " #ppE    ppp&pp ",
      " % *     p   h  ",
      " %      (p   W  ",
      " %)     (p +Rd  ",
      " %-[]]]{ pdddd  ",
      " #%ZZZZZ%p      ",
      "                "
    ],
    [
      "                ",
      " ppZZppZZppZZpp ",
      " Z}   p  \\p  |Z ",
      " Z`   p   p  :Z ",
      " Z;   pxxxx  'Z ",
      " p    p       p ",
      " #ppppppppppppp ",
      " Z  E      p  Z ",
      " Z  E      p  Z ",
      " #ppE    pppppp ",
      " %       p   d  ",
      " Z       p   d  ",
      " Z       pU, d  ",
      " Z .///< pdd>?  ",
      " #%ZZZZZ%p      ",
      "                "
    ],
    [
      "                ",
      " ppkkppkkppkkpp ",
      " %    p   p   % ",
      " %    p   p   % ",
      " %    pxxxx   % ",
      " p    p       p ",
      " #ppppppppppppp ",
      " %  E      p  % ",
      " %  E      pf % ",
      " #ppE    pppppp ",
      " %       p   >  ",
      " %       p\u00a3  >  ",
      " %       p,  >  ",
      " %       peWWd  ",
      " #%%%%%%%p      ",
      "                "
    ],
    [
      "                ",
      " pppppppppppppp ",
      " pddddp\u00a4\u00a4\u00a4ddddp ",
      " pddddp\u00a4\u00a4\u00a4ddddp ",
      " pddddpdddddddp ",
      " pddddpdddddddp ",
      " pppppppppppppp ",
      " p\u00a4\u00a4dddddddpddp ",
      " p\u00a4\u00a4dddddddpddp ",
      " pdddddddpppppp ",
      " pdddddddpU  d  ",
      " pdddddddpc  d  ",
      " pdddddddp   d  ",
      " pdddddddpdddd  ",
      " ppppppppp      ",
      "                "
    ]
  ]
}