{
  "name": "multi_hospital_2_ground",
  "refpalette": "c70cities:multi_hospital_2_ground_palette",
  "xsize": 16,
  "zsize": 16,
  "slices": [
    [
      "GGGGGGGGGGGGGGGG",
      "aaaaaaaaaaaaaaaG",
      "aaaabbbbbbbbbbaG",
      "caaabbbbbbbbbbaG",
      "daaadGGdGGdGGdaG",
      "caaaaaaaaaaaaaaG",
      "caaaaaaaaaaaaaaG",
      "caaaaaaaaaaaaaaG",
      "caaaaaaaaaaaaaaG",
      "cceeeeeeeeeeeeaG",
      "cceeee!eeeeeeeaG",
      "cceeeeeeeeeeeeaG",
      "cceeeeeeeeeeeeaG",
      "cceeeeeeeeeeeeaG",
      "ccccccccccccccaG",
      "ccccccccccccccaG"
    ],
    [
      "                ",
      "                ",
      " f              ",
      "gh   ij ij ij   ",
      "kh  llllllllll  ",
      " h              ",
      " m              ",
      " h              ",
      "ngggggggggggggo ",
      " p   p   p   qo ",
      " q r q r q r qo ",
      "sqtthqtthqtt qo ",
      "squu quu q u qo ",
      "sqw  qw  qx  qo ",
      "sqyyAyyyAyyyAyo ",
      "            BGC "
    ],
    [
      "                ",
      "                ",
      " f              ",
      "gh              ",
      "kh              ",
      " h              ",
      " D              ",
      " h              ",
      "nggEEggEEggEEgo ",
      " F   F   F   qo ",
      " q   q   q   qo ",
      " qIJ qKJ qL  qo ",
      " q   q   q   qo ",
      " qL  qL  q   qo ",
      " qyyMyyyMyyyMyo ",
      "             NO "
    ],
    [
      "                ",
      "                ",
      " f              ",
      "gh              ",
      "kh              ",
      " h              ",
      " h              ",
      " h              ",
      "nggEEggEEggEEgo ",
      " P   P   P   qo ",
      " q   q   q   qo ",
      " q   q   q   qo ",
      " q   q   q   qo ",
      " qQR qQR qQR qo ",
      " qyySyyySyyySyo ",
      "             TO "
    ],
    [
      "                ",
      "                ",
      " f              ",
      "gh              ",
      " h              ",
      " h              ",
      " h              ",
      " h              ",
      "ngggggggggggggo ",
      " q   q   q   qo ",
      " q   q   q   qo ",
      " q   q   q   qo ",
      " q   q   q   qo ",
      " q U qVU qWX qo ",
      " qyyyyyyyyyyyyo ",
      "              O "
    ],
    [
      "                ",
      "                ",
      " f              ",
      "gh              ",
      " h              ",
      " h              ",
      " h              ",
      " h              ",
      "nYZZZZZZZZZZZZo ",
      " q           qo ",
      " q           qo ",
      " q           qo ",
      " q           qo ",
      " q           qo ",
      " qyyyyyyyyyyyyo ",
      "              O "
    ]
  ]
}