{
  "name": "multi_condo1_2_floor3",
  "refpalette": "c70cities:multi_condo1_2_floor3_palette",
  "xsize": 16,
  "zsize": 16,
  "slices": [
    [
      "   abcccddefgggg",
      "   abcccddeeeeee",
      " hhhbddddddddccc",
      "  ijbddddddddccc",
      "  ijbddddddddccc",
      "  ijbddddddddddd",
      "  ijbddddddddddd",
      "  ijbddddddddddd",
      "  ijbddddddddddd",
      "  ijbddddddddddd",
      "  ijbddddddddddd",
      "  ijbbbbbbbbkkkb",
      "  ijjjjjjjhaaaaa",
      "  iiiiiiiihlllll",
      "          h     ",
      "                "
    ],
    [
      "    m  n  o     ",
      "    bpqpr bbsbbb",
      " hhhbt pu pw p x",
      "   jby pA pw B C",
      "   jbD pE pr pFp",
      "   jbI n  pu p D",
      "   jbpppJ pA B I",
      "   jbKKLM pE ppp",
      "   jb  L  pJNKK!",
      "   jb   O pL   P",
      "   jbQR   pLM  S",
      "   jbbTTTbbbU Ub",
      "   jjjjjjjh     ",
      "          hlllll",
      "          h     ",
      "                "
    ],
    [
      "    lV W  X     ",
      "    bpYp Zbb0bbb",
      " hhhb1 p  p  p2 ",
      "    b  p3 p  4  ",
      "    b  p5 p6 p7p",
      "    b  W  p  pZ8",
      "    bppp9 p3 4 @",
      "    b#$   p5 ppp",
      "    b     p9    ",
      "    b     p%    ",
      "    b     p     ",
      "    bbUUUbbbU Ub",
      "          h     ",
      "          h     ",
      "          h     ",
      "                "
    ],
    [
      "    l^ p  &     ",
      "    bppp  bb*bbb",
      " hhhb  p  p  p( ",
      "    b  p  p  p  ",
      "    b  p  p  ppp",
      "    b  p  p  p #",
      "    bppp  p  p )",
      "    b     p  ppp",
      "    b     p     ",
      "    b     p     ",
      "    b     p     ",
      "    bbUUUbbbUUUb",
      "          h     ",
      "          h     ",
      "          h     ",
      "                "
    ],
    [
      "    b  p  b     ",
      "    bppp  bbbbbb",
      " hhhb  p  p  p  ",
      "   +b  p  p  p  ",
      "   +b  p  p  ppp",
      "   +b  p  p  p  ",
      "   +bppp  p  p  ",
      "   +b     p  ppp",
      "   +b     p     ",
      "   +b     p     ",
      "   +b     p     ",
      "   +bbbbbbbbbbbb",
      "   +++++++h     ",
      "          h     ",
      "          h     ",
      "                "
    ],
    [
      "    b-----b     ",
      "    b-----bbbbbb",
      " hhhb-----------",
      "   [b-----------",
      "   [b-----------",
      "   [b-----------",
      "   [b-----------",
      "   [b-----------",
      "   [b-----------",
      "   [b-----------",
      "   [b-----------",
      "   [bbbbbbbbbbbb",
      "   [[[[[[[h     ",
      "          h]]]]]",
      "          h     ",
      "                "
    ]
  ]
}