{
  "name": "multi_militarybase_0_ground",
  "refpalette": "c70cities:multi_militarybase_0_ground_palette",
  "xsize": 16,
  "zsize": 16,
  "slices": [
    [
      "zzzzzzzzzzzzzzzz",
      "zaaaaaaaaaaaaaaa",
      "zabzzbzbbzbzzzzz",
      "zazzzzbbbbzbbbbb",
      "zazbzzzbcccccccc",
      "zazzzzbbcddddddd",
      "zazzzzbzcedddddd",
      "zazzzzzbc dddddd",
      "zazzbzzbc dddddd",
      "zabbzzbbc dddccc",
      "zazzzzzbcddddccc",
      "zazbzzbzcddddccc",
      "zazzzzzbcddddccc",
      "fabzzbbbcccccccc",
      "ghbbbbzbbbbbbbbb",
      "ghbbbbbbbbbbbbbb"
    ],
    [
      "                ",
      " aaaaaaaaaaaaaaa",
      " ai j j ij j j j",
      " a  j           ",
      " aj  j  kkkkkkkk",
      " a   j  kl   e m",
      " a jj   k n     ",
      " a j j  k n     ",
      " a    j k n  op ",
      " ai  j  k n  kkq",
      " aj j j kr   k  ",
      " aj  j  k  stk  ",
      " a  j   kuuuuk  ",
      "wa      kkkkkk  ",
      "w x             ",
      "      x        x"
    ],
    [
      "                ",
      " aaaaaaaaaaaaaaa",
      " ai     i       ",
      " a              ",
      " a      yAAAAyyy",
      " a      y     e ",
      " a      A       ",
      " a      A       ",
      " a      y    oB ",
      " ai     y    yyC",
      " a      A    y  ",
      " a      A    A  ",
      " a      yDEF y  ",
      " a      yyAAyy  ",
      "                ",
      "                "
    ],
    [
      "                ",
      " aaaaaaaaaaaaaaa",
      " ai     i       ",
      " a       IIII   ",
      " a      yyyyyyyy",
      " a     Iy      e",
      " a     Iy       ",
      " a     Iy       ",
      " a     Iy    o  ",
      " ai    Iy    yyy",
      " a     Iy    y  ",
      " a     Iy    A  ",
      " a     Iy    y  ",
      " a      yyAAyy  ",
      "                ",
      "                "
    ],
    [
      "                ",
      " aaaaaaaaaaaaaaa",
      " ai     i       ",
      " a              ",
      " a      yJJJJyyy",
      " a      yKKKKK  ",
      " a      JK      ",
      " a      JK      ",
      " a      yK   oKK",
      " ai     yK   yyJ",
      " a      JK   y  ",
      " a      JK   y  ",
      " a      yK   y  ",
      " a      yyyyyy  ",
      "                ",
      "                "
    ],
    [
      "                ",
      " LLMMMMMNMMMMMMM",
      " LOPPPPPPOPPPPPP",
      " wQ      e      ",
      " wQ     kkkkkkkk",
      " wQ     kRRRRR  ",
      " wQ     kRRRRRRR",
      " wQ     kRRRRRRR",
      " SQ     kRRRRoRR",
      "TUQ     kRRRRkkk",
      " wQ     kRRRRk  ",
      " w      kRRRRk  ",
      " w      kRRRRk  ",
      " w      kRRRRk  ",
      "        kVVVVk  ",
      "        kVVVVk  "
    ]
  ]
}