{
  "name": "multi_laboratory1_10_base2",
  "refpalette": "c70cities:multi_laboratory1_10_base2_palette",
  "xsize": 16,
  "zsize": 16,
  "slices": [
    [
      "vvvvvvvvvvvvvvvv",
      "aaaaaaaaaaaaaaav",
      "bbbbbbbbbbbbbcav",
      "    d========cav",
      "  e d========cav",
      "ddddd========cav",
      "    d========cav",
      "    d========cav",
      "    d========cav",
      "    d========cav",
      "    d========cav",
      " f  d========cav",
      " fggd========cav",
      "hhhhd========cav",
      "hhhhd========cav",
      "dddddiiiiiiiicav"
    ],
    [
      "vvvvvvvvvvvvvvvv",
      "aaaaaaaaaaaaaaav",
      "bbbbbbbbbbbbbcav",
      "  ejklmnnn opbav",
      "   jkq      rbav",
      "kkkkdst     !bav",
      "    ku      pbav",
      "    kw xxx  rbav",
      "    kw yAy  ubav",
      "    kB yAy opbav",
      "    kC yAy  Dbav",
      "hh  kE ArA Bubav",
      "ggF k   I    bav",
      "    k       Jbav",
      "    K       Jbav",
      "Lkkkdkkkkkkkkcav"
    ],
    [
      "vvvvvvvvvvvvvvvv",
      "aaaaaaaaaaaaaaav",
      "bbbbbbbbbbbbbcav",
      " e  k      opbav",
      "    k       Dbav",
      "kkkkds      ubav",
      "    ku     opbav",
      "    ku xxx  rbav",
      "    k  MMM  ubav",
      "hh  k  MMN  pbav",
      "ggF k  MMM  rbav",
      "  F k  rrr  ubav",
      "    k   O    bav",
      "    k        bav",
      "    P       Qbav",
      "Rkkkdkkkkkkkkcav"
    ],
    [
      "vvvvvvvvvvvvvvvv",
      "aaaaaaaaaaaaaaav",
      "bbbbbbbbbbbbbcav",
      "e   k       sbav",
      "    k       rbav",
      "kkkkds      ubav",
      "hhhhku      sbav",
      "hhhhk  xxx  rbav",
      "ggF k   M   ubav",
      "  F k  MMM  sbav",
      "    k   M   rbav",
      "    k       ubav",
      "    k        bav",
      "    k        bav",
      "S   k       Tbav",
      "Ukkkdkkkkkkkkcav"
    ],
    [
      "vvvvvvvvvvvvvvvv",
      "aaaaaaaaaaaaaaav",
      "bbbbbbbbbbbbbcav",
      "    ks      Vbav",
      "e   ks      sbav",
      "kkkkds      sbav",
      "    ks      Vbav",
      "    kWX     sbav",
      " fggkWX     sbav",
      "  hhkWX     Vbav",
      "    kWX     sbav",
      "    ks      sbav",
      "    kssssssssbav",
      "    k       sbav",
      "    k       sbav",
      "kkkkdkkkkkkkkcav"
    ],
    [
      "vvvvvvvvvvvvvvvv",
      "aaaaaaaaaaaaaaav",
      "bbbbbbbbbbbbbcav",
      "    kYYYYYYYYbav",
      " e  kYYYYYYYYbav",
      "kkkkdYYYYYYYYbav",
      "    kYYYYYYYYbav",
      "    kYYYYYYYYbav",
      "    kYYYYYYYYbav",
      " f  kYYYYYYYYbav",
      " fggkYYYYYYYYbav",
      "  hhkYYYYYYYYbav",
      "    kYYYYYYYYbav",
      "    kYYYYYYYYbav",
      "    kYYYYYYYYbav",
      "kkkkdkkkkkkkkcav"
    ]
  ]
}