{
  "name": "multi_condo1_0_ground",
  "refpalette": "c70cities:multi_condo1_0_ground_palette",
  "xsize": 16,
  "zsize": 16,
  "slices": [
    [
      "GGGGGGGGGGGGGGGG",
      "GGGGGGGGGGGGGGGG",
      "GGGGaaaaaaaaaaaa",
      "GGGGabbbbbabbbbb",
      "GGGGaaaaaaabbbbb",
      "GGGGabbbbbbbbbbb",
      "GGGGabbbbbbbbbbb",
      "GGGGabbbbbbbbbbb",
      "GGGGabbbbbbbbbbb",
      "GGGGabbbbbbbbbbb",
      "GGccabbbbbbbbbbb",
      "GGGbabbbbbbbbbbb",
      "GGGbabbbbbbbbbbb",
      "Gdddabbbbbbbbbbb",
      "GGGbabbbbbbbbbbb",
      "GGGbabbbbbbbbbbb"
    ],
    [
      "                ",
      "                ",
      "  e aaaaaaaaaaaa",
      "    afffffafffff",
      "  e aaaaaaaaaaaa",
      "    aghijihkjghi",
      "  e alhijihmjlhi",
      "    a   j   j   ",
      "  e a           ",
      "    a   nhn  n  ",
      "  ccaop  n  nhn ",
      "    aq          ",
      "    aqp   r r p ",
      " dddao    sttts ",
      "    abu  ubuuuuu",
      "    wx    yABBC "
    ],
    [
      "                ",
      "                ",
      "  D             ",
      "          a     ",
      "  D EEEEEEaEEEEE",
      "    E   j   j F ",
      "  D E   j F j   ",
      "    E   j   j   ",
      "  D E           ",
      "    E           ",
      "  cca        I  ",
      "    a           ",
      "    aI          ",
      " ddda          J",
      "    abK  KbKKKKK",
      "    L     D     "
    ],
    [
      "                ",
      "                ",
      "  K             ",
      "          a     ",
      "  K EEEEEEaEEEEE",
      "    E           ",
      "  K E           ",
      "    E           ",
      "  K E           ",
      "    E           ",
      "  cca           ",
      "    a           ",
      "    a           ",
      " ddda         J ",
      "    ab    b     ",
      "    L           "
    ],
    [
      "                ",
      "                ",
      "  K             ",
      "          a     ",
      "  K EEEEEEaEEEEE",
      "    E           ",
      "  K E     M     ",
      "    E           ",
      "  K E           ",
      "    E           ",
      "  cca           ",
      "    a           ",
      "    aN    M     ",
      " ddda        J  ",
      "    ab    b     ",
      "    a           "
    ],
    [
      "                ",
      "                ",
      "  O             ",
      "          a     ",
      "  O EEEEEEaEEEEE",
      "    E           ",
      "  O E     P     ",
      "    E           ",
      "  O E           ",
      "    E           ",
      "  cca           ",
      "    a           ",
      "    aQ    P     ",
      " ddda       J   ",
      "    ab    b     ",
      "    a           "
    ]
  ]
}