{
  "name": "multi_militarybase_4_base1",
  "refpalette": "c70cities:multi_militarybase_4_base1_palette",
  "xsize": 16,
  "zsize": 16,
  "slices": [
    [
      "vvvvvvvvvvvvvvvv",
      "avaaaaaaavaaaavv",
      "abaaaaaaabaaaavv",
      "abaaaaaaabaaaavv",
      "abaaaaaaabaaaavv",
      "bvbbbbbbbvbbbvvv",
      "abaaaaaaabaaaavv",
      "abaaaaaaabaaaavv",
      "abaaaaaaabaaaavv",
      "cvdaaaaaabaaaavv",
      "ebeeaaaaabaaaavv",
      "ebeeeaaaabaaaavv",
      "ebeeeaaaabaaaavv",
      "bvbbbbbbbvbbbvvv",
      " beeeaaaaaaaaavv",
      " beeeaaaaaaaaavv"
    ],
    [
      "vvvvvvvvvvvvvvvv",
      "fv  ggg!hviiiivv",
      " j k   lhm  iivv",
      " no p q  r  iivv",
      " j       mi  ivv",
      "sv       vtttvvv",
      " j       muupwvv",
      " no      mup xvv",
      " j       mk yABv",
      "svd      C   ABv",
      "      DD mE  ABv",
      "     FDDFmIo Jvv",
      "       F mIo Kvv",
      "Lv       vtttvvv",
      " L    F   MNMNvv",
      " L   FDD      vv"
    ],
    [
      "vvvvvvvvvvvvvvvv",
      "fv  kq qhv iiivv",
      "        Om   ivv",
      " P       Q    vv",
      "         m    vv",
      "sv       vtttvvv",
      "         muu  vv",
      " P       m   Rvv",
      "         m    Bv",
      "sv       S    Bv",
      "         m    Bv",
      "       T m   Rvv",
      "         mU   vv",
      " v       vtttvvv",
      "          MMMMvv",
      "              vv"
    ],
    [
      "vvvvvvvvvvvvvvvv",
      "fv       v  iivv",
      "         m   Vvv",
      "         m    vv",
      "         m    vv",
      "sv       vtttvvv",
      "         mp   vv",
      "         m    vv",
      "         m    Bv",
      "svW      m    Bv",
      "         m    Bv",
      "         m    vv",
      "         m    vv",
      " v       vtttvvv",
      "          MXXMvv",
      "              vv"
    ],
    [
      "vvvvvvvvvvvvvvvv",
      "fv       v   Vvv",
      " L       m   Vvv",
      " L       m    vv",
      " L       m    vv",
      "svLLLLLLLvtttvvv",
      " L       L    vv",
      " L       L    vv",
      " L       L   YBv",
      "sv       L   YBv",
      "         L   YBv",
      "         L    vv",
      "         L    vv",
      "Zv       vtttvvv",
      " Z            vv",
      " Z            vv"
    ],
    [
      "vvvvvvvvvvvvvvvv",
      "0v0000000v0000vv",
      "1b1111111b1110vv",
      "1b1111111b1110vv",
      "1b1111111b1110vv",
      "bvbbbbbbbvbbbvvv",
      "1b1111111b1110vv",
      "1b1111111b1110vv",
      "1b1111111b111!vv",
      "1v1111111b1110vv",
      "1b1111111b1110vv",
      "1b1111111b1110vv",
      "1b1111111b1110vv",
      "bvbbbbbbbvbbbvvv",
      "2b111111111110vv",
      "2b111111111110vv"
    ]
  ]
}