{
  "name": "multi_militarybase_1_ground",
  "refpalette": "c70cities:multi_militarybase_1_ground_palette",
  "xsize": 16,
  "zsize": 16,
  "slices": [
    [
      "abcccccccccccccc",
      "abcccccccccccccc",
      "deczczzcffffffff",
      "zezzzzccfggggfff",
      "zezzzzzzfggggfff",
      "zezczzzcfggggfff",
      "zeczzzzcf gggfff",
      "zezzczzcf gggggg",
      "zezzzzzcf gggggg",
      "zezzzzczfhgggggg",
      "zezzzzzcfggggggg",
      "zezzczzcffffffff",
      "zeczzzczcccczzcc",
      "zecczzzcczzzzczz",
      "zeeeeeeeeeeeeeee",
      "zzzzzzzzzzzzzzzz"
    ],
    [
      "i j  j   j   j  ",
      "i  j            ",
      " e      kkkkkk  ",
      " ell l  kmmmmk  ",
      " el   llkn o k  ",
      " e    l kp   k  ",
      " eq l   k r  kks",
      " e l  l k r  tu ",
      " e l    k r     ",
      " el     k r     ",
      " e    l kw   h x",
      " el  l  kkkkkkkk",
      " e              ",
      " eqyll  q l l  l",
      " eeeeeeeeeeeeeee",
      "                "
    ],
    [
      "                ",
      "                ",
      " e      AABBAA  ",
      " e      ACD EA  ",
      " e      B    B  ",
      " e      B    A  ",
      " eq     A    AAF",
      " e      A    tE ",
      " e      B       ",
      " e      B       ",
      " e      A     h ",
      " e      ABBBBAAA",
      " e              ",
      " eq     q       ",
      " eeeeeeeeeeeeeee",
      "                "
    ],
    [
      "                ",
      "                ",
      " e      AABBAA  ",
      " e     IA    A  ",
      " e     IA    B  ",
      " e     IA    A  ",
      " eq    IA    AAA",
      " e     IA    t  ",
      " e     IA       ",
      " e     IA       ",
      " e     IA      h",
      " e      AAAAAAAA",
      " e       IIII   ",
      " eq     q       ",
      " eeeeeeeeeeeeeee",
      "                "
    ],
    [
      "                ",
      "                ",
      " e      AAAAAA  ",
      " e      AJ   A  ",
      " e      KJ   A  ",
      " e      KJ   A  ",
      " eq     AJ   AAK",
      " e      AJ   tJJ",
      " e      KJ      ",
      " e      KJ      ",
      " e      AJJJJJ  ",
      " e      AKKKKAAA",
      " e              ",
      " eq     q       ",
      " eeeeeeeeeeeeeee",
      "                "
    ],
    [
      "        kLLLLk  ",
      "        kLLLLk  ",
      " i      kMMMMk  ",
      " i      kMMMMk  ",
      " i      kMMMMk  ",
      " iN     kMMMMk  ",
      "OPN     kMMMMkkk",
      " QN     kMMMMtMM",
      " iN     kMMMMMMM",
      " iN     kMMMMMMM",
      " iN     kMMMMM  ",
      " iN     kkkkkkkk",
      " iN      h      ",
      " RSTTTTTTSTTTTTT",
      " RRUUUUUVUUUUUUU",
      "                "
    ]
  ]
}