{
  "name": "multi_militarybase_3_ground",
  "refpalette": "c70cities:multi_militarybase_3_ground_palette",
  "xsize": 16,
  "zsize": 16,
  "slices": [
    [
      "aaaaaaaaaaaaaaaa",
      "aaaaaaaaaaaaaaaa",
      "bbbbbbbbaaaaaaaa",
      "bbbcdbbbaaaaaaaa",
      "bbbbbbbbaaaaaaaa",
      "bbbbbbbbaaaaaaaa",
      "bbbeeeebaaaaaaaa",
      "eeeeeeebaaffaffa",
      "eeeeeeebaaffaffa",
      "eeeeeeebaaffaffa",
      "eeeeeeebaaaaaaaa",
      "bbbbbbbbzaaaaaaa",
      "aaaazaaaaazzzzaz",
      "zzazzzzaazazzaaz",
      "gggggggggggggggg",
      "zzzzzzzzzzzzzzzz"
    ],
    [
      "     h          ",
      "                ",
      "  iiiiiijjjjj jj",
      "  ickllim   n  j",
      "  i   oi        ",
      "  i   pi n      ",
      "qiirstri  uw uw ",
      " x    yi  f! ff ",
      "      Ai  ff ff ",
      "      Ai mff ffB",
      "CD    !i    n   ",
      "iiiiiiiijjjjjjjj",
      "                ",
      "   E E F E EI   ",
      "gggggggggggggggg",
      "                "
    ],
    [
      "                ",
      "                ",
      "  JJJJJJjjjjj jj",
      "  Jc KKJ       j",
      "  L    L        ",
      "  J    L        ",
      "MJJrNOrJ  PQ PQ ",
      " R     J  ff ff ",
      "       L  ffcffc",
      "       L  SS SS ",
      " T    UJ        ",
      "JJJLLLLJjjjjjjjj",
      "                ",
      "       F   I    ",
      "gggggggggggggggg",
      "                "
    ],
    [
      "                ",
      "                ",
      "  JJJJJJjjjjj jj",
      "  Jc kkJV      j",
      "  L    JV       ",
      "  J    JV       ",
      "JJJrrrrJV       ",
      "       JV ff ff ",
      "       JV ff ff ",
      "       JV       ",
      "      UJV       ",
      "JJJJJJJJjjjjjjjj",
      "   VVVV         ",
      "       F  I     ",
      "gggggggggggggggg",
      "                "
    ],
    [
      "                ",
      "                ",
      "  JJJJJJWWWWWWWW",
      "  Jc oXJ       W",
      "  Jo  XY        ",
      "  J   XY        ",
      "YJJXXXXJ        ",
      "XX    XJ  ZZ ZZ ",
      "      XY  ZZ ZZ ",
      "      XY        ",
      "I XXXXXJ        ",
      "JJJYYYYJWWWWWWWW",
      "                ",
      "       F I      ",
      "gggggggggggggggg",
      "                "
    ],
    [
      "  i0000i        ",
      "  i0000i        ",
      "  i1111i        ",
      "  ic111i        ",
      "  i1111i        ",
      "  i1111i        ",
      "iii1111i        ",
      "1111111i        ",
      "1111111i        ",
      "1111111i        ",
      " I11111i        ",
      "iiiiiiii        ",
      "      I         ",
      "222222322       ",
      "4444444564444744",
      "                "
    ]
  ]
}