{
  "name": "multi_factory_0_ground",
  "refpalette": "c70cities:multi_factory_0_ground_palette",
  "xsize": 16,
  "zsize": 16,
  "slices": [
    [
      "zaazzzzzzzzzzzzz",
      "aaazzzzzzzzzzzzz",
      "aazbbbbbbbbbbbzz",
      "aaabbbbbbbbbbbzz",
      "aaabbbbbbbbbbbzz",
      "zaabbbbbbbbbbbzz",
      "zaabbbbbbbbbbbzz",
      "aaabbbbbbbbbbbzz",
      "zaabbbbbbbbbbbzz",
      "aaabbbbbbbbbbbzz",
      "aaabbbbbbbbbbbzz",
      "aaabbbbbbbbbbbzz",
      "zaabbbbbbbbbbbzz",
      "aaabbbbbbbbbbbzz",
      "zaabbbbbbbbbbbzz",
      "aaabbbbbbbbbbbzz"
    ],
    [
      "                ",
      "                ",
      "   ccccccccccc  ",
      "   cdeffdgh dc  ",
      "   ij    k  lc  ",
      "   c     mnnnc  ",
      "   co    p  lc  ",
      "   coq   gr  c  ",
      "   co    ssssc  ",
      "   co q     tc  ",
      "   c uwwxy j c  ",
      "   cmmmmmmmAmc  ",
      "   cddBdd    c  ",
      "      C      c  ",
      "             c  ",
      "             c  "
    ],
    [
      "                ",
      "                ",
      "   ccccccccccc  ",
      "   cd ffdg  dc  ",
      "   D     E  Fc  ",
      "   c     mnnnc  ",
      "   IJ    K  Fc  ",
      "   IL    g   c  ",
      "   IL    ssssc  ",
      "   I        tc  ",
      "   c   M     c  ",
      "   cmIIIImmNmc  ",
      "   cOPQPR    c  ",
      "      S      c  ",
      "             c  ",
      "             c  "
    ],
    [
      "                ",
      "                ",
      "   ccTUVcTUVcc  ",
      "   cd   dg  dc  ",
      "   I     g   c  ",
      "   c     mnnnc  ",
      "   I     g   c  ",
      "   I     g   c  ",
      "   I     ssssc  ",
      "   I        tc  ",
      "   c         c  ",
      "   cmIIIImmmmc  ",
      "   c  W    XYc  ",
      "   Z         c  ",
      "   Z         c  ",
      "   Z         c  "
    ],
    [
      "                ",
      "                ",
      "   ccccccccccc  ",
      "   cd   dg  dc  ",
      "  0c     g   c  ",
      "  0c     mnnnc  ",
      "  0c     g   c  ",
      "  0c     g   c  ",
      "  0c     ssssc  ",
      "  0c        tc  ",
      "   c         c  ",
      "   cmmmmmmmmmc  ",
      "   c  1      c  ",
      "  0c2        c  ",
      "  0c2        c  ",
      "  0c2        c  "
    ],
    [
      "                ",
      "                ",
      "   ccccccccccc  ",
      "   cd   dbbbdc  ",
      "   c    3bbbbc  ",
      "   c    3bbbbc  ",
      "   c    3bbbbc  ",
      "   c    3bbbbc  ",
      "   c    3bbbbc  ",
      "   c    3bbbtc  ",
      "   c    3bbbbc  ",
      "   cmmmmmmmmmc  ",
      "   c        4c  ",
      "   c         c  ",
      "   c         c  ",
      "   c         c  "
    ]
  ]
}