{
  "name": "multi_laboratory1_10_base4",
  "refpalette": "c70cities:multi_laboratory1_10_base4_palette",
  "xsize": 16,
  "zsize": 16,
  "slices": [
    [
      "vvvvvvvvvvvvvvvv",
      "aaaaaaaaaaaaaaav",
      "bbbbccccccccccav",
      "    d========cav",
      "  e d========cav",
      "ddddd========cav",
      "    d========cav",
      "    d========cav",
      "    d========cav",
      "    d========cav",
      "    d========cav",
      " f  d========cav",
      " fggd========cav",
      "hhhhd========cav",
      "hhhhd========cav",
      "dddddiiiiiiiicav"
    ],
    [
      "vvvvvvvvvvvvvvvv",
      "aaaaaaaaaaaaaaav",
      "bbbbbbbbbbbbbcav",
      "  ejklmnnn opbav",
      "   jkq      rbav",
      "kkkkdst     ubav",
      "    kw      pbav",
      "    kx yyy  rbav",
      "    kx ABA  wbav",
      "    ku ABA opbav",
      "    kC ABA  Dbav",
      "hh  kE BrB uwbav",
      "ggF k   I    bav",
      "    k       Jbav",
      "    K       Jbav",
      "Lkkkdkkkkkkkkcav"
    ],
    [
      "vvvvvvvvvvvvvvvv",
      "aaaaaaaaaaaaaaav",
      "bbbbbbbbbbbbbcav",
      " e  k!     opbav",
      "    k       Dbav",
      "kkkkds      wbav",
      "    kw     opbav",
      "    kw yyy  rbav",
      "    k  MMM  wbav",
      "hh  k  MMN  pbav",
      "ggF k  MMM  rbav",
      "  F k  rrr  wbav",
      "    k   O    bav",
      "    k        bav",
      "    P       Qbav",
      "Rkkkdkkkkkkkkcav"
    ],
    [
      "vvvvvvvvvvvvvvvv",
      "aaaaaaaaaaaaaaav",
      "bbbbbbbbbbbbbcav",
      "e   k       sbav",
      "    k       rbav",
      "kkkkds      wbav",
      "hhhhkw      sbav",
      "hhhhk  yyy  rbav",
      "ggF k   M   wbav",
      "  F k  MMM  sbav",
      "    k   M   rbav",
      "    k       wbav",
      "    k        bav",
      "    k        bav",
      "S   k       Tbav",
      "Ukkkdkkkkkkkkcav"
    ],
    [
      "vvvvvvvvvvvvvvvv",
      "aaaaaaaaaaaaaaav",
      "bbbbbbbbbbbbbcav",
      "    ks      Vbav",
      "e   ks      sbav",
      "kkkkds      sbav",
      "    ks      Vbav",
      "    kWX     sbav",
      " fggkWX     sbav",
      "  hhkWX     Vbav",
      "    kWX     sbav",
      "    ks      sbav",
      "    kssssssssbav",
      "    k       sbav",
      "    k       sbav",
      "kkkkdkkkkkkkkcav"
    ],
    [
      "vvvvvvvvvvvvvvvv",
      "aaaaaaaaaaaaaaav",
      "bbbbbbbbbbbbbcav",
      "    kYYYYYYYYbav",
      " e  kYYYYYYYYbav",
      "kkkkdYYYYYYYYbav",
      "    kYYYYYYYYbav",
      "    kYYYYYYYYbav",
      "    kYYYYYYYYbav",
      " f  kYYYYYYYYbav",
      " fggkYYYYYYYYbav",
      "  hhkYYYYYYYYbav",
      "    kYYYYYYYYbav",
      "    kYYYYYYYYbav",
      "    kYYYYYYYYbav",
      "kkkkdkkkkkkkkcav"
    ]
  ]
}