{
  "name": "multi_condo1_4_ground",
  "refpalette": "c70cities:multi_condo1_4_ground_palette",
  "xsize": 16,
  "zsize": 16,
  "slices": [
    [
      "aaaaaabHHHHHHHHH",
      "aaaaaaabbbbbbccG",
      "aaaaaaadddddbaGG",
      "aaaaaaadddddbaGG",
      "aaaaaaadddddbaGG",
      "aaaaaaadddddbccG",
      "aaaaaaabbbbbbaGG",
      "aaaaaaa     aaGG",
      "aaaaaaa     aaGG",
      "aaaaaaa     baGG",
      "aaaaaae     bccG",
      "aaaaaafbbbbbbaGG",
      "aaaaaaaag   baGG",
      "aaaaaaaah   baGG",
      "aaaaaabbbbbbbccG",
      "aaaaaabHHHHHHHHH"
    ],
    [
      "      b         ",
      "      bbbbbbbcc ",
      "      i  jklb   ",
      "   m  b     n   ",
      "   m  b o o b   ",
      "p  m  bqrrrqbcc ",
      "ps m  bbbbbbb   ",
      "p  m  b     t   ",
      "p  m  u     t   ",
      "ps m  w     b   ",
      "p  m xb     bcc ",
      "   m  bbbbbbb   ",
      "   m  b     n   ",
      "      y Ah  b   ",
      "      bbbbbbbcc ",
      "      b         "
    ],
    [
      "      b         ",
      "     Bbbbbbbbcc ",
      "      C     b   ",
      "   D  bE    F   ",
      "   D  b     b   ",
      "   D  bIJJK bcc ",
      "   D  bbbbbbb   ",
      "L  D  b     t   ",
      "   D  M     t   ",
      "   D  N     b   ",
      "L  D  b     bcc ",
      "   D  bbbbbbb   ",
      "   D  b     F   ",
      "      O  Ah b   ",
      "      bbbbbbbcc ",
      "      b         "
    ],
    [
      "      b         ",
      "      bbbbbbbcc ",
      "      P     b   ",
      "   D  b     F   ",
      "   D  b     b   ",
      "   D  b JKJ bcc ",
      "   D  bbbbbbb   ",
      "   D Qb     t   ",
      "   D  P     t   ",
      "   D  P     b   ",
      "   D Rb     bcc ",
      "   D  bbbbbbb   ",
      "   D  b   PhF   ",
      "      P   Aab   ",
      "      bbbbbbbcc ",
      "      b         "
    ],
    [
      "      b     b   ",
      "      bbbbbbbcc ",
      "      b     b   ",
      "   D  b     b   ",
      "   D  b     b   ",
      "   D  b     bcc ",
      "   D  bbbbbbb   ",
      "   D Sb     t   ",
      "   D  b     t   ",
      "   D  b     b   ",
      "   D Sb     bcc ",
      "   D  bbbbbbb   ",
      "   D  b  Pg b   ",
      "      b     b   ",
      "      bbbbbbbcc ",
      "      b     b   "
    ],
    [
      "      bdddddb   ",
      "      bbbbbbbcc ",
      "      bT    b   ",
      "   D  bT    b   ",
      "   D  bT    b   ",
      "   D  bTTTTTbcc ",
      "   D  bbbbbbb   ",
      "   D  b     t   ",
      "   D  b     t   ",
      "   D  b     b   ",
      "   D  b     bcc ",
      "   D  bbbbbbb   ",
      "   D  b Pg  b   ",
      "      b     b   ",
      "      bbbbbbbcc ",
      "      bdddddb   "
    ]
  ]
}