{
  "name": "multi_laboratory1_10_base3",
  "refpalette": "c70cities:multi_laboratory1_10_base3_palette",
  "xsize": 16,
  "zsize": 16,
  "slices": [
    [
      "vvvvvvvvvvvvvvvv",
      "aaaaaaaaaaaaaaav",
      "bbbbbbbbbbbbbcav",
      "    d========cav",
      "  e d========cav",
      "ddddd========cav",
      "    d========cav",
      "    d========cav",
      "    d========cav",
      "    d========cav",
      "    d========cav",
      " f  d========cav",
      " fggd========cav",
      "hhhhd========cav",
      "hhhhd========cav",
      "dddddiiiiiiiicav"
    ],
    [
      "vvvvvvvvvvvvvvvv",
      "aaaaaaaaaaaaaaav",
      "bbbbbbbbbbbbbcav",
      "  ejklm    nobav",
      "   jkp      qbav",
      "kkkkdrs     tbav",
      "    ku      obav",
      "    kw      qbav",
      "    kw      ubav",
      "    kt     nobav",
      "    kx      qbav",
      "hh  ky     tubav",
      "ggA k       !bav",
      "    k       Bbav",
      "    C       Bbav",
      "Dkkkdkkkkkkkkcav"
    ],
    [
      "vvvvvvvvvvvvvvvv",
      "aaaaaaaaaaaaaaav",
      "bbbbbbbbbbbbbcav",
      " e  k      nobav",
      "    k        bav",
      "kkkkdr      ubav",
      "    ku     nobav",
      "    ku       bav",
      "    k       ubav",
      "hh  k       obav",
      "ggA k        bav",
      "  A k       ubav",
      "    k        bav",
      "    k        bav",
      "    E       Fbav",
      "Ikkkdkkkkkkkkcav"
    ],
    [
      "vvvvvvvvvvvvvvvv",
      "aaaaaaaaaaaaaaav",
      "bbbbbbbbbbbbbcav",
      "e   k       rbav",
      "    k        bav",
      "kkkkdr      ubav",
      "hhhhku      rbav",
      "hhhhk        bav",
      "ggA k       ubav",
      "  A k       rbav",
      "    k        bav",
      "    k       ubav",
      "    k        bav",
      "    k        bav",
      "J   k       Kbav",
      "Lkkkdkkkkkkkkcav"
    ],
    [
      "vvvvvvvvvvvvvvvv",
      "aaaaaaaaaaaaaaav",
      "bbbbbbbbbbbbbcav",
      "    kr      Mbav",
      "e   kr      rbav",
      "kkkkdr      rbav",
      "    kr      Mbav",
      "    kNO     rbav",
      " fggkNO     rbav",
      "  hhkNO     Mbav",
      "    kNO     rbav",
      "    kr      rbav",
      "    krrrrrrrrbav",
      "    k       rbav",
      "    k       rbav",
      "kkkkdkkkkkkkkcav"
    ],
    [
      "vvvvvvvvvvvvvvvv",
      "aaaaaaaaaaaaaaav",
      "bbbbbbbbbbbbbcav",
      "    kPPPPPPPPbav",
      " e  kPPPPPPPPbav",
      "kkkkdPPPPPPPPbav",
      "    kPPPPPPPPbav",
      "    kPPPPPPPPbav",
      "    kPPPPPPPPbav",
      " f  kPPPPPPPPbav",
      " fggkPPPPPPPPbav",
      "  hhkPPPPPPPPbav",
      "    kPPPPPPPPbav",
      "    kPPPPPPPPbav",
      "    kPPPPPPPPbav",
      "kkkkdkkkkkkkkcav"
    ]
  ]
}