{
  "name": "multi_laboratory1_12_base2",
  "refpalette": "c70cities:multi_laboratory1_12_base2_palette",
  "xsize": 16,
  "zsize": 16,
  "slices": [
    [
      " abbbbbbbbbbbcdv",
      " abbbbbbbbbbbcdv",
      " abbbbbbbbbbbcdv",
      "eabbbbbbbbbbbcdv",
      "abbbfbbbbbbbbcdv",
      "abbbbbbbbbbbbcdv",
      "bbbbbbbbbbbbbcdv",
      "bbbbbbbbbbbbbcdv",
      "bbbbbbbbbbbbbcdv",
      "bbbbbbbbbbbbbcdv",
      "bbbbbbbbbbbbbcdv",
      "bbbbfbbbbbbbbcdv",
      "bbbbbbbbbbbbbcdv",
      "bbbbbbbbbbbbbcdv",
      "bbbbbbbbbbbbbcdv",
      "bbbbbbbbbbbbbcdv"
    ],
    [
      " g  h    i jkldv",
      " g  m     njkldv",
      " g  o       jjdv",
      "eg  p        cdv",
      "ge  f q     rcdv",
      "gs  p tu    jjdv",
      "    pwxxx  jyldv",
      "    pAxxxB jyldv",
      "    p  C  D jjdv",
      "    pE   qB  cdv",
      "    p!FII I rcdv",
      "J  efppppppppcdv",
      "    p       Kcdv",
      "    o        cdv",
      "    L    i  Mcdv",
      "    N     BOMcdv"
    ],
    [
      " g  P      gkldv",
      " g  Q      gkldv",
      " g  o       gjdv",
      "eg  p       Rcdv",
      "gS  f       rcdv",
      "g   p       gjdv",
      "    T UV   gyldv",
      "    TV WV  gyldv",
      "    T       gjdv",
      "    T       Rcdv",
      "    p       rcdv",
      "   Sfppppppppcdv",
      "    p        cdv",
      "    o        cdv",
      "    X       Ycdv",
      "    Z       0cdv"
    ],
    [
      " g  o      gkldv",
      " g  o      gkldv",
      " g  o       gjdv",
      "eg  p        cdv",
      "gS  f       rcdv",
      "g   p       gjdv",
      "    T      gyldv",
      "    T      gyldv",
      "    T       gjdv",
      "    T        cdv",
      "    p       rcdv",
      "   Sfppppppppcdv",
      "    p        cdv",
      "    o        cdv",
      "    o        cdv",
      "    o        cdv"
    ],
    [
      " g  p      g1ldv",
      " g  p      g1ldv",
      " g  p       gjdv",
      "eg  p       Rcdv",
      "g   f       2cdv",
      "g   p       gjdv",
      "    p      gyldv",
      "    p      gyldv",
      "    p       gjdv",
      "    p       Rcdv",
      "    p  3  4 2cdv",
      "    fppppppppcdv",
      "    p        cdv",
      "    p       5cdv",
      "    p        cdv",
      "    p        cdv"
    ],
    [
      " g667889889j@ldv",
      " g66788988#j@ldv",
      " g6678898898jjdv",
      "eg66788888888cdv",
      "g666f88888888cdv",
      "g666788#88#8jjdv",
      "66667889889j@ldv",
      "66667889889j@ldv",
      "6666788988#8jjdv",
      "6666788888888cdv",
      "66667$$$$$$$$cdv",
      "6666fppppppppcdv",
      "66667$888888$cdv",
      "66967$888888$cdv",
      "66967$898898$cdv",
      "66967$8#8898$cdv"
    ]
  ]
}