{
  "name": "multi_hospital_0_base2",
  "refpalette": "c70cities:multi_hospital_0_base2_palette",
  "xsize": 16,
  "zsize": 16,
  "slices": [
    [
      "vvvvvvvvvvvvvvvv",
      "vvvvvvvvvvvvvvvv",
      "vvvvvvvvvvvvvvvv",
      "vvvvvvvvvvvvvvvv",
      "vvvvvvvvvvvvvvvv",
      "vvvvvvvvvvvvvvvv",
      "vvvvvvvvvvvvvvvv",
      "vvvvvvvvvvvvvvvv",
      "vvvvvvvvvaaaavvv",
      "vvvvvvvvvabbavvv",
      "vvvvvvvvvabbavvv",
      "vvvvvvvvvaacavvv",
      "vvvvvvvvvvvvvvvv",
      "vvvvvvvvvvvvvvvv",
      "vvvvvvvvvvvvvvvv",
      "vvvvvvvvvvvvvvvv"
    ],
    [
      "vvvvvvvvvvvvvvvv",
      "vddddddddddddddd",
      "vddddddddddddddd",
      "vddddddddeeeeeee",
      "vddddddddeffffff",
      "vddddddddeffffff",
      "vddddddddeffffff",
      "vddddddddeffffff",
      "vddddddddfaaafff",
      "vddddddddabbgfff",
      "vddddddddabbgfff",
      "vddddddddabaafff",
      "vddddddddevvefff",
      "vddddddddeffffff",
      "vddddddddeffffff",
      "vddddddddeffffff"
    ],
    [
      "vvvvvvvvvvvvvvvv",
      "vddddddddddddddd",
      "vddddddddddddddd",
      "vddddddddeeeeeee",
      "vdddddddde  h h ",
      "vddddddddehiiii ",
      "vdddddddde iiiih",
      "vdddddddde h h  ",
      "vddddddddfaaa   ",
      "vddddddddaj k   ",
      "vdddddddda  l   ",
      "vdddddddda aa   ",
      "vddddddddevvm   ",
      "vddddddddemmm   ",
      "vdddddddde      ",
      "vddddddddeih  i "
    ],
    [
      "vvvvvvvvvvvvvvvv",
      "vddddddddddddddd",
      "vddddddddddddddd",
      "vddddddddeeeeeee",
      "vdddddddde      ",
      "vdddddddde n  o ",
      "vdddddddde p n  ",
      "vdddddddde      ",
      "vddddddddfaaa   ",
      "vdddddddda  q   ",
      "vdddddddda  r   ",
      "vdddddddda aas  ",
      "vddddddddevvm   ",
      "vddddddddemmm   ",
      "vdddddddde      ",
      "vdddddddde    t "
    ],
    [
      "vvvvvvvvvvvvvvvv",
      "vddddddddddddddd",
      "vddddddddddddddd",
      "vddddddddeeeeeee",
      "vdddddddde      ",
      "vdddddddde      ",
      "vdddddddde      ",
      "vdddddddde      ",
      "vddddddddfaaa   ",
      "vdddddddda  u   ",
      "vdddddddda  u   ",
      "vdddddddda aa   ",
      "vddddddddevvm   ",
      "vddddddddemmm   ",
      "vdddddddde      ",
      "vdddddddde      "
    ],
    [
      "vvvvvvvvvvvvvvvv",
      "vddddddddddddddd",
      "vddddddddddddddd",
      "vddddddddeeeeeee",
      "vddddddddewwwwww",
      "vddddddddewwwwww",
      "vddddddddewwwwww",
      "vddddddddewwwwww",
      "vddddddddfaaawww",
      "vdddddddda  awww",
      "vdddddddda  awww",
      "vdddddddda cawww",
      "vddddddddevvmwww",
      "vddddddddemmmwww",
      "vddddddddewwwwww",
      "vddddddddewwwwww"
    ]
  ]
}