{
  "name": "multi_megatower1_0_ground",
  "refpalette": "c70cities:multi_megatower1_0_ground_palette",
  "xsize": 16,
  "zsize": 16,
  "slices": [
    [
      "HHHGaGGGGaGGGGaG",
      "HHHGGaaGaGaaGaaa",
      "HHHGGGaGGGGGGaGG",
      "HHHvvvvvvvvvvvvv",
      "HHHvvvvvvvvvvvvv",
      "HHHvvvvvvvvvvvvv",
      "HHHvvvbvvvvvvbvv",
      "HHHvvvvvvvvvvvvv",
      "HHHvvvvvvvvvvvvv",
      "HHHvvvvvvvvvvvvv",
      "HHHvvvvvvvvvvvvv",
      "HHHvvvvvvvvvvvvv",
      "HHHvvvvvvvvvvvvv",
      "HHHvvvbvvvvvvbvv",
      "HHHvvvvvvvvvvv  ",
      "HHHvvvvvvvvvvv  "
    ],
    [
      "                ",
      "                ",
      "   c d dddddc dd",
      "   eeefeeeeeefee",
      "   e!g       hij",
      "   eg       ig h",
      "  kfg bllllllbll",
      "   e  mnoooonm p",
      "   e  m    q m  ",
      "   e  mq     mr ",
      "   e  m      lst",
      "   e  m      u  ",
      "   e  m     wlgx",
      "  kf  byAyyyybyy",
      "   e  mB CCDDE  ",
      "   e  F      E  "
    ],
    [
      "                ",
      "                ",
      "                ",
      "   eeefeeeeeefee",
      "   eg           ",
      "   e            ",
      "   f  bllllllbll",
      "   e  mIJIKIIm L",
      "   e  m      m  ",
      "   e  m      m  ",
      "   e  m      lsM",
      "   e  m      N  ",
      "   e  m      l  ",
      "   f  byOyyyybyy",
      "   e  m    PQERR",
      "   e  S      ERT"
    ],
    [
      "                ",
      "                ",
      "      U      U  ",
      "   eeefeeeeeefee",
      "   eg g         ",
      "   e         g  ",
      "   f  bllllllbll",
      "   e  mKKJIKJm  ",
      "   e  m      m  ",
      "   e  m      m  ",
      "   e  m      lss",
      "   e  m     Vl  ",
      "   e  m      l  ",
      "   f  byyyyyybyy",
      "   e  m W   XERR",
      "   e  m      ERR"
    ],
    [
      "                ",
      "                ",
      "                ",
      "   eeefeeeeeefee",
      "   e  g     gY  ",
      "   e  g     ggg ",
      "   f  bllllllbll",
      "   e  mIIKIIIl  ",
      "   e  m      l  ",
      "   e  m      l  ",
      "   e  m      lZZ",
      "   e  m      l  ",
      "   e  m      lg ",
      "   f  bZZZZZZbyy",
      "   e  Z      Z  ",
      "   e  Z      Z  "
    ],
    [
      "                ",
      "                ",
      "                ",
      "   eeefeeeeeefee",
      "   e00b000000b00",
      "   e00b000000b00",
      "  0fbbbbbbbbbbbb",
      "  0Z00b000000bll",
      "  0Z00b000000bll",
      "  0Z00b000000bll",
      "  0Z00b000000bll",
      "  0Z00b000000b00",
      "  0Z00b000000b00",
      "  0fbbbbbbbbbbbb",
      "   e00b000000b  ",
      "   e00b000000b  "
    ]
  ]
}